Workbook

Sheet Campaigns
A1: Date | B1: Campaign | C1: Tests | D1: Description | E1: Comment
A2: 42885 | B2: plant-gonfreville-2017 | C2: 21 | D2: Total dataset plant_gonfreville_2017,gdoc
A3: 42906 | B3: tests_campaign-lacq-2017 | C3: 34
A4: 43054 | B4: leak-anechoic_chamber-2017 | C4: 78
A5: 43202 | B5: leak-anechoic_chamber-2018 | C5: 17
A6: 43208 | B6: leak-outside-2018 | C6: 27
A7: 43256 | B7: tests_campaign-lacq-jun2018 | C7: 68
A8: 43389 | B8: tests_campaign-lacq-oct2018 | C8: 50
A9: 43619 | B9: tadi-2019 | C9: =28+27+68+49+32+52+26 -> 282 | E9: Date correspondant au déploiement du système,
A10: 43655 | B10: sobegi-july-2019 | C10: 0 | E10: Pas de test, uniquement du bruit de fond,
A11: 43831 | B11: tadi-2020 | C11: =169+56 -> 225 | E11: 141 tests spécifiques pour l'acoustique,
A12: 43831 | B12: ineris-2020 | C12: 111 | E12: Nous n'avons pas les 111 enregistrées, Valeur à mettre à jour
A13: 44197 | B13: tadi-2021 | C13: 193
B14: TOTAL | C14: =SUM(C2:C13) -> 1106
A16: Campaign | B16: Date | C16: Tests
A17: Nombre total d'essais réalisés | C17: =SUM(C18:C83) -> 1636
A18: {=UNIQUE(Tests!A4:A1001)} -> tadi_jun_2018 | B18: =IFERROR(__xludf.DUMMYFUNCTION("JOIN("" - "", TRANSPOSE(UNIQUE(FILTER(Tests!C$4:C1001, Tests!A$4:A1001=A18))))"),"05-06-2018") -> 05-06-2018 | C18: =IFERROR(__xludf.DUMMYFUNCTION("COUNTUNIQUE(FILTER(Tests!G$4:G1001, Tests!C$4:C1001=B18))"),1.0) -> 1
B19: =IFERROR(__xludf.DUMMYFUNCTION("JOIN("" - "", TRANSPOSE(UNIQUE(FILTER(Tests!C$4:C1001, Tests!A$4:A1001=A19))))"),"05-06-2018 - 06-06-2018 - 07-06-2018 - 08-06-2018 - 16-10-2018 - 17-10-2018 - 18-10-2018 - 19-10-2018 - 15-10-2019 - 16-10-2019 - 22-10-2019 - 06-03-2020 - 30-06-2020 - 22-09-2020 - 23-09-2020 - 29-09-2020 - 30-09-2020 - 01-10-2020 - 19-10-2020 - 04-11-20"&"20 - 05-11-2020 - 06-11-2020 - 10-11-2020 - 12-11-2020 - 19-11-2020 - 25-11-2020 - 30-11-2020 - 01-12-2020 - 02-12-2020 - 15-12-2020 - 16-12-2020 - 05-01-2021 - 19-01-2021 - 20-01-2021 - 21-01-2021 - 02-03-2021 - 03-03-2021 - 11-03-2021 - 01-04-2021 - 02-"&"04-2021 - 14-04-2021 - 16-04-2021 - 05-05-2021 - 07-05-2021 - 27-05-2021 - 01-06-2021 - 02-06-2021 - 11-06-2021 - 21-06-2021 - 22-06-2021 - 08-07-2021 - 09-07-2021 - - 22-07-2021 - 27-07-2021 - 07-09-2021 - 08-09-2021 - 09-09-2021 - 10-09-2021 - 20-09-20"&"21 - 21-09-2021 - 29-09-2021 - 15-10-2021 - 21-10-2021 - 05-11-2021 - 25-11-2021 - 26-11-2021 - 02-12-2021 - 06-12-2021 - 07-12-2021 - 14-12-2021 - 15-12-2021 - 19-01-2022 - 25-01-2022 - 01-02-2022 - 02-02-2022 - 24-02-2022 - 31-03-2022 - 05-04-2022 - 06-"&"04-2022 - 12-04-2022 - 04-05-2022 - 16-05-2022 - 08-06-2022 - 21-06-2022 - 22-06-2022 - 23-06-2022 - 24-06-2022 - 28-06-2022 - 01-07-2022 - 04-07-2022 - 05-07-2022 - 06-07-2022 - 07-07-2022 - 29-07-2022 - 29-09-2022 - 10-10-2022 - 11-10-2022 - 13-10-2022 "&"- 18-10-2022 - 19-10-2022 - 21-10-2022 - 02-11-2022 - 07-11-2022 - 08-11-2022 - 01-12-2022 - 07-12-2022 - 11-01-2023 - 13-01-2023 - 23-01-2023 - 25-01-2023 - 30-01-2023 - 02-02-2023 - 06-09-2023 - 23-04-2024 - 25-04-2024 - 15-05-2024 - 27-05-2024 - 10-06-"&"2024 - 14-06-2024 - 17-06-2024 - 18-06-2024 - 19-06-2024 - 20-06-2024 - 21-06-2024 - 24-06-2024 - 25-06-2024 - 26-06-2024 - 27-06-2024 - 28-06-2024 - 08-07-2024 - 09-07-2024 - 10-07-2024 - 11-07-2024 - 12-07-2024 - 16-07-2024 - 17-07-2024 - 22-07-2024 - 2"&"3-07-2024 - 03-09-2024 - 09-09-2024 - 10-09-2024 - 11-09-2024 - 12-09-2024 - 13-09-2024 - 16-09-2024 - 17-09-2024 - 18-09-2024 - 19-09-2024 - 20-09-2024 - 01-10-2024 - 02-10-2024 - 03-10-2024 - 08-10-2024 - 21-10-2024 - 23-10-2024 - 24-10-2024 - 25-10-202"&"4 - 28-10-2024 - 29-10-2024 - 31-10-2024 - 06-11-2024 - 08-11-2024 - 18-11-2024 - 19-11-2024 - 20-11-2024 - 22-11-2024 - 25-11-2024 - 26-11-2024 - 27-11-2024 - 28-11-2024 - 29-11-2024 - 02-12-2024 - 03-12-2024 - 04-12-2024 - 05-12-2024 - 09-12-2024 - 10-1"&"2-2024 - 11-12-2024 - 12-12-2024 - 16-12-2024 - 18-12-2024 - 19-12-2024 - 20-12-2024 - 10-10-2025 - 17-10-2025 - 20-10-2025 - 21-10-2025 - 22-10-2025 - 30-10-2025 - 31-10-2025 - 05-11-2025 - 06-11-2025") -> 05-06-2018 - 06-06-2018 - 07-06-2018 - 08-06-2018 - 16-10-2018 - 17-10-2018 - 18-10-2018 - 19-10-2018 - 15-10-2019 - 16-10-2019 - 22-10-2019 - 06-03-2020 - 30-06-2020 - 22-09-2020 - 23-09-2020 - 29-09-2020 - 30-09-2020 - 01-10-2020 - 19-10-2020 - 04-11-2020 - 05-11-2020 - 06-11-2020 - 10-11-2020 - 12-11-2020 - 19-11-2020 - 25-11-2020 - 30-11-2020 - 01-12-2020 - 02-12-2020 - 15-12-2020 - 16-12-2020 - 05-01-2021 - 19-01-2021 - 20-01-2021 - 21-01-2021 - 02-03-2021 - 03-03-2021 - 11-03-2021 - 01-04-2021 - 02-04-2021 - 14-04-2021 - 16-04-2021 - 05-05-2021 - 07-05-2021 - 27-05-2021 - 01-06-2021 - 02-06-2021 - 11-06-2021 - 21-06-2021 - 22-06-2021 - 08-07-2021 - 09-07-2021 - - 22-07-2021 - 27-07-2021 - 07-09-2021 - 08-09-2021 - 09-09-2021 - 10-09-2021 - 20-09-2021 - 21-09-2021 - 29-09-2021 - 15-10-2021 - 21-10-2021 - 05-11-2021 - 25-11-2021 - 26-11-2021 - 02-12-2021 - 06-12-2021 - 07-12-2021 - 14-12-2021 - 15-12-2021 - 19-01-2022 - 25-01-2022 - 01-02-2022 - 02-02-2022 - 24-02-2022 - 31-03-2022 - 05-04-2022 - 06-04-2022 - 12-04-2022 - 04-05-2022 - 16-05-2022 - 08-06-2022 - 21-06-2022 - 22-06-2022 - 23-06-2022 - 24-06-2022 - 28-06-2022 - 01-07-2022 - 04-07-2022 - 05-07-2022 - 06-07-2022 - 07-07-2022 - 29-07-2022 - 29-09-2022 - 10-10-2022 - 11-10-2022 - 13-10-2022 - 18-10-2022 - 19-10-2022 - 21-10-2022 - 02-11-2022 - 07-11-2022 - 08-11-2022 - 01-12-2022 - 07-12-2022 - 11-01-2023 - 13-01-2023 - 23-01-2023 - 25-01-2023 - 30-01-2023 - 02-02-2023 - 06-09-2023 - 23-04-2024 - 25-04-2024 - 15-05-2024 - 27-05-2024 - 10-06-2024 - 14-06-2024 - 17-06-2024 - 18-06-2024 - 19-06-2024 - 20-06-2024 - 21-06-2024 - 24-06-2024 - 25-06-2024 - 26-06-2024 - 27-06-2024 - 28-06-2024 - 08-07-2024 - 09-07-2024 - 10-07-2024 - 11-07-2024 - 12-07-2024 - 16-07-2024 - 17-07-2024 - 22-07-2024 - 23-07-2024 - 03-09-2024 - 09-09-2024 - 10-09-2024 - 11-09-2024 - 12-09-2024 - 13-09-2024 - 16-09-2024 - 17-09-2024 - 18-09-2024 - 19-09-2024 - 20-09-2024 - 01-10-2024 - 02-10-2024 - 03-10-2024 - 08-10-2024 - 21-10-2024 - 23-10-2024 - 24-10-2024 - 25-10-2024 - 28-10-2024 - 29-10-2024 - 31-10-2024 - 06-11-2024 - 08-11-2024 - 18-11-2024 - 19-11-2024 - 20-11-2024 - 22-11-2024 - 25-11-2024 - 26-11-2024 - 27-11-2024 - 28-11-2024 - 29-11-2024 - 02-12-2024 - 03-12-2024 - 04-12-2024 - 05-12-2024 - 09-12-2024 - 10-12-2024 - 11-12-2024 - 12-12-2024 - 16-12-2024 - 18-12-2024 - 19-12-2024 - 20-12-2024 - 10-10-2025 - 17-10-2025 - 20-10-2025 - 21-10-2025 - 22-10-2025 - 30-10-2025 - 31-10-2025 - 05-11-2025 - 06-11-2025 | C19: =IFERROR(__xludf.DUMMYFUNCTION("COUNTUNIQUE(FILTER(Tests!G$4:G1001, Tests!A$4:A1001=A19))"),1368.0) -> 1368
A20: tadi_oct_2018 | B20: =IFERROR(__xludf.DUMMYFUNCTION("JOIN("" - "", TRANSPOSE(UNIQUE(FILTER(Tests!C$4:C1001, Tests!A$4:A1001=A20))))"),"16-10-2018") -> 16-10-2018 | C20: =IFERROR(__xludf.DUMMYFUNCTION("COUNTUNIQUE(FILTER(Tests!G$4:G1001, Tests!A$4:A1001=A20))"),1.0) -> 1
A21: tadi_2019 | B21: =IFERROR(__xludf.DUMMYFUNCTION("JOIN("" - "", TRANSPOSE(UNIQUE(FILTER(Tests!C$4:C1001, Tests!A$4:A1001=A21))))"),"06-06-2019 - 19-06-2019 - 20-06-2019 - 18-07-2019 - 23-07-2019 - 25-07-2019 - 30-07-2019 - 01-08-2019 - 06-08-2019") -> 06-06-2019 - 19-06-2019 - 20-06-2019 - 18-07-2019 - 23-07-2019 - 25-07-2019 - 30-07-2019 - 01-08-2019 - 06-08-2019 | C21: =IFERROR(__xludf.DUMMYFUNCTION("COUNTUNIQUE(FILTER(Tests!G$4:G1001, Tests!A$4:A1001=A21))"),164.0) -> 164
A22: Campagne acoustique oct 2019 | B22: =IFERROR(__xludf.DUMMYFUNCTION("JOIN("" - "", TRANSPOSE(UNIQUE(FILTER(Tests!C$4:C1001, Tests!A$4:A1001=A22))))"),"15-10-2019") -> 15-10-2019 | C22: =IFERROR(__xludf.DUMMYFUNCTION("COUNTUNIQUE(FILTER(Tests!G$4:G1001, Tests!A$4:A1001=A22))"),1.0) -> 1
A23: W43 - 26 tests | B23: =IFERROR(__xludf.DUMMYFUNCTION("JOIN("" - "", TRANSPOSE(UNIQUE(FILTER(Tests!C$4:C1001, Tests!A$4:A1001=A23))))"),"22-10-2019") -> 22-10-2019 | C23: =IFERROR(__xludf.DUMMYFUNCTION("COUNTUNIQUE(FILTER(Tests!G$4:G1001, Tests!A$4:A1001=A23))"),1.0) -> 1
A24: Tests de la portée pour Alarme IMC Service + Flir G300a dans une camionnette - pluie ; grêle, vent de 3 à 20 m/s | B24: =IFERROR(__xludf.DUMMYFUNCTION("JOIN("" - "", TRANSPOSE(UNIQUE(FILTER(Tests!C$4:C1001, Tests!A$4:A1001=A24))))"),"06-03-2020") -> 06-03-2020 | C24: =IFERROR(__xludf.DUMMYFUNCTION("COUNTUNIQUE(FILTER(Tests!G$4:G1001, Tests!A$4:A1001=A24))"),1.0) -> 1
A25: Tests acoustiques | B25: =IFERROR(__xludf.DUMMYFUNCTION("JOIN("" - "", TRANSPOSE(UNIQUE(FILTER(Tests!C$4:C1001, Tests!A$4:A1001=A25))))"),"30-06-2020 - 22-09-2020 - 15-12-2020") -> 30-06-2020 - 22-09-2020 - 15-12-2020 | C25: =IFERROR(__xludf.DUMMYFUNCTION("COUNTUNIQUE(FILTER(Tests!G$4:G1001, Tests!A$4:A1001=A25))"),3.0) -> 3
A26: LQA-Scientific Aviation / Campagne Environnement | B26: =IFERROR(__xludf.DUMMYFUNCTION("JOIN("" - "", TRANSPOSE(UNIQUE(FILTER(Tests!C$4:C1001, Tests!A$4:A1001=A26))))"),"29-09-2020") -> 29-09-2020 | C26: =IFERROR(__xludf.DUMMYFUNCTION("COUNTUNIQUE(FILTER(Tests!G$4:G1001, Tests!A$4:A1001=A26))"),1.0) -> 1
A27: Tests Satellite pour LQA | B27: =IFERROR(__xludf.DUMMYFUNCTION("JOIN("" - "", TRANSPOSE(UNIQUE(FILTER(Tests!C$4:C1001, Tests!A$4:A1001=A27))))"),"16-10-2020 - 29-10-2020 - 21-01-2021") -> 16-10-2020 - 29-10-2020 - 21-01-2021 | C27: =IFERROR(__xludf.DUMMYFUNCTION("COUNTUNIQUE(FILTER(Tests!G$4:G1001, Tests!A$4:A1001=A27))"),3.0) -> 3
A28: Tests Environnement LQA | B28: =IFERROR(__xludf.DUMMYFUNCTION("JOIN("" - "", TRANSPOSE(UNIQUE(FILTER(Tests!C$4:C1001, Tests!A$4:A1001=A28))))"),"19-10-2020 - 09-11-2020 - 20-11-2020") -> 19-10-2020 - 09-11-2020 - 20-11-2020 | C28: =IFERROR(__xludf.DUMMYFUNCTION("COUNTUNIQUE(FILTER(Tests!G$4:G1001, Tests!A$4:A1001=A28))"),3.0) -> 3
A29: essai pour installation IMC Service + FLIRG300a ; vent à 1 m/s du nord vers le sud | B29: =IFERROR(__xludf.DUMMYFUNCTION("JOIN("" - "", TRANSPOSE(UNIQUE(FILTER(Tests!C$4:C1001, Tests!A$4:A1001=A29))))"),"04-11-2020") -> 04-11-2020 | C29: =IFERROR(__xludf.DUMMYFUNCTION("COUNTUNIQUE(FILTER(Tests!G$4:G1001, Tests!A$4:A1001=A29))"),1.0) -> 1
A30: essai pour installation IMC Service + FLIRG300a ; vent à 4 m/s et venant de l'est l'après-midi | B30: =IFERROR(__xludf.DUMMYFUNCTION("JOIN("" - "", TRANSPOSE(UNIQUE(FILTER(Tests!C$4:C1001, Tests!A$4:A1001=A30))))"),"05-11-2020") -> 05-11-2020 | C30: =IFERROR(__xludf.DUMMYFUNCTION("COUNTUNIQUE(FILTER(Tests!G$4:G1001, Tests!A$4:A1001=A30))"),1.0) -> 1
A31: essai pour installation du système IMC Service + FLIR G300a | B31: =IFERROR(__xludf.DUMMYFUNCTION("JOIN("" - "", TRANSPOSE(UNIQUE(FILTER(Tests!C$4:C1001, Tests!A$4:A1001=A31))))"),"06-11-2020") -> 06-11-2020 | C31: =IFERROR(__xludf.DUMMYFUNCTION("COUNTUNIQUE(FILTER(Tests!G$4:G1001, Tests!A$4:A1001=A31))"),1.0) -> 1
A32: Tests environnement LQA | B32: =IFERROR(__xludf.DUMMYFUNCTION("JOIN("" - "", TRANSPOSE(UNIQUE(FILTER(Tests!C$4:C1001, Tests!A$4:A1001=A32))))"),"19-10-2020 - 09-11-2020 - 20-11-2020") -> 19-10-2020 - 09-11-2020 - 20-11-2020 | C32: =IFERROR(__xludf.DUMMYFUNCTION("COUNTUNIQUE(FILTER(Tests!G$4:G1001, Tests!A$4:A1001=A32))"),3.0) -> 3
A33: Tests installation IMC Service | B33: =IFERROR(__xludf.DUMMYFUNCTION("JOIN("" - "", TRANSPOSE(UNIQUE(FILTER(Tests!C$4:C1001, Tests!A$4:A1001=A33))))"),"12-11-2020") -> 12-11-2020 | C33: =IFERROR(__xludf.DUMMYFUNCTION("COUNTUNIQUE(FILTER(Tests!G$4:G1001, Tests!A$4:A1001=A33))"),1.0) -> 1
A34: Tests ACOEM / Robotique | B34: =IFERROR(__xludf.DUMMYFUNCTION("JOIN("" - "", TRANSPOSE(UNIQUE(FILTER(Tests!C$4:C1001, Tests!A$4:A1001=A34))))"),"30-11-2020") -> 30-11-2020 | C34: =IFERROR(__xludf.DUMMYFUNCTION("COUNTUNIQUE(FILTER(Tests!G$4:G1001, Tests!A$4:A1001=A34))"),1.0) -> 1
A35: Tests Rebellion et IMC Services | B35: =IFERROR(__xludf.DUMMYFUNCTION("JOIN("" - "", TRANSPOSE(UNIQUE(FILTER(Tests!C$4:C1001, Tests!A$4:A1001=A35))))"),"05-01-2021") -> 05-01-2021 | C35: =IFERROR(__xludf.DUMMYFUNCTION("COUNTUNIQUE(FILTER(Tests!G$4:G1001, Tests!A$4:A1001=A35))"),1.0) -> 1
A36: Tests pour Com | B36: =IFERROR(__xludf.DUMMYFUNCTION("JOIN("" - "", TRANSPOSE(UNIQUE(FILTER(Tests!C$4:C1001, Tests!A$4:A1001=A36))))"),"07-01-2021") -> 07-01-2021 | C36: =IFERROR(__xludf.DUMMYFUNCTION("COUNTUNIQUE(FILTER(Tests!G$4:G1001, Tests!A$4:A1001=A36))"),1.0) -> 1
A37: Tests pour Rebellion | B37: =IFERROR(__xludf.DUMMYFUNCTION("JOIN("" - "", TRANSPOSE(UNIQUE(FILTER(Tests!C$4:C1001, Tests!A$4:A1001=A37))))"),"19-01-2021") -> 19-01-2021 | C37: =IFERROR(__xludf.DUMMYFUNCTION("COUNTUNIQUE(FILTER(Tests!G$4:G1001, Tests!A$4:A1001=A37))"),1.0) -> 1
A38: Tests pour LQA | B38: =IFERROR(__xludf.DUMMYFUNCTION("JOIN("" - "", TRANSPOSE(UNIQUE(FILTER(Tests!C$4:C1001, Tests!A$4:A1001=A38))))"),"20-01-2021 - 11-03-2021 - 16-04-2021 - 04-05-2021 - 05-05-2021 - 06-05-2021 - 07-05-2021 - 27-05-2021 - 31-05-2021 - 02-06-2021 - 21-06-2021 - 22-07-2021") -> 20-01-2021 - 11-03-2021 - 16-04-2021 - 04-05-2021 - 05-05-2021 - 06-05-2021 - 07-05-2021 - 27-05-2021 - 31-05-2021 - 02-06-2021 - 21-06-2021 - 22-07-2021 | C38: =IFERROR(__xludf.DUMMYFUNCTION("COUNTUNIQUE(FILTER(Tests!G$4:G1001, Tests!A$4:A1001=A38))"),12.0) -> 12
A39: Tests satellite pour LQA | B39: =IFERROR(__xludf.DUMMYFUNCTION("JOIN("" - "", TRANSPOSE(UNIQUE(FILTER(Tests!C$4:C1001, Tests!A$4:A1001=A39))))"),"16-10-2020 - 29-10-2020 - 21-01-2021") -> 16-10-2020 - 29-10-2020 - 21-01-2021 | C39: =IFERROR(__xludf.DUMMYFUNCTION("COUNTUNIQUE(FILTER(Tests!G$4:G1001, Tests!A$4:A1001=A39))"),3.0) -> 3
A40: Tests acoustiques 02 et 03 mars 2021 | B40: =IFERROR(__xludf.DUMMYFUNCTION("JOIN("" - "", TRANSPOSE(UNIQUE(FILTER(Tests!C$4:C1001, Tests!A$4:A1001=A40))))"),"02-03-2021") -> 02-03-2021 | C40: =IFERROR(__xludf.DUMMYFUNCTION("COUNTUNIQUE(FILTER(Tests!G$4:G1001, Tests!A$4:A1001=A40))"),1.0) -> 1
A41: Tests acoustiques Robot-POD Acoem 01 et 02 avril 2021 | B41: =IFERROR(__xludf.DUMMYFUNCTION("JOIN("" - "", TRANSPOSE(UNIQUE(FILTER(Tests!C$4:C1001, Tests!A$4:A1001=A41))))"),"01-04-2021") -> 01-04-2021 | C41: =IFERROR(__xludf.DUMMYFUNCTION("COUNTUNIQUE(FILTER(Tests!G$4:G1001, Tests!A$4:A1001=A41))"),1.0) -> 1
...

Sheet Dataset
B1: GAZ | C1: Nombre | D1: %
B2: Nbre catégorie | C2: =IFERROR(__xludf.DUMMYFUNCTION("COUNTUNIQUE(Tests!M$4:M1018)"),10.0) -> 10 | D2: OK
B3: Somme | C3: =SUM(C4:C11) -> 2235
B4: {=UNIQUE(Tests!M$4:M1018)} -> N2 | C4: =COUNTIF(Tests!M$4:M1018,B4) -> 608 | D4: =C4/C$3 -> 0.27203579
B5: CH4 | C5: =COUNTIF(Tests!M$4:M1018,B5) -> 1479 | D5: =C5/C$3 -> 0.66174497
B6: unknown | C6: =COUNTIF(Tests!M$4:M1018,B6) -> 28 | D6: =C6/C$3 -> 0.012527964
B7: CO2 | C7: =COUNTIF(Tests!M$4:M1018,B7) -> 117 | D7: =C7/C$3 -> 0.052348993
C8: =COUNTIF(Tests!M$4:M1018,B8) -> 0 | D8: =C8/C$3 -> 0
B9: 20% C2H6 | C9: =COUNTIF(Tests!M$4:M1018,B9) -> 1 | D9: =C9/C$3 -> 0.00044742729
B10: 50% C3H8 | C10: =COUNTIF(Tests!M$4:M1018,B10) -> 1 | D10: =C10/C$3 -> 0.00044742729
B11: 20% C3H8 | C11: =COUNTIF(Tests!M$4:M1018,B11) -> 1 | D11: =C11/C$3 -> 0.00044742729
B12: C2H6 | C12: =COUNTIF(Tests!M$4:M1018,B12) -> 3 | D12: =C12/C$3 -> 0.0013422819
B13: C3H8 | C13: =COUNTIF(Tests!M$4:M1018,B13) -> 7 | D13: =C13/C$3 -> 0.0031319911
B14: H2
B15: Multifuites | C15: Nombre | D15: %
B16: Nbre catégorie | C16: =IFERROR(__xludf.DUMMYFUNCTION("COUNTUNIQUE(Tests!AU4:AU1018)"),2.0) -> 2 | D16: OK
B17: Oui | C17: =COUNTIF(Tests!AU4:AU1018,"Y") -> 96 | D17: =C17/C19 -> 0.063957362
B18: Non | C18: =COUNTIF(Tests!AU4:AU1018,"N") -> 1405 | D18: =C18/C19 -> 0.93604264
B19: Somme | C19: =SUM(C17:C18) -> 1501
B20: Non renseigné | C20: =COUNTBLANK(Tests!AU$4:AU1018) -> 5182 | D20: Purges
B22: Débit | C22: Nombre | D22: %
B23: Nbre catégorie | C23: =IFERROR(__xludf.DUMMYFUNCTION("COUNTUNIQUE(Tests!AT4:AT1018)"),4.0) -> 4 | D23: OK
B24: 0-1 | C24: =COUNTIF(Tests!U$4:U1018,"<1") -> 364 | D24: =C24/C$27 -> 0.19601508
B25: 1-10 | C25: =COUNTIFS(Tests!U$4:U1018,">=1",Tests!U$4:U1018,"<10") -> 1157 | D25: =C25/C$27 -> 0.62304793
B26: 10+ | C26: =COUNTIF(Tests!U$4:U1018,">=10") -> 336 | D26: =C26/C$27 -> 0.180937
B27: Somme | C27: =SUM(C24:C26) -> 1857
B28: Non renseigné | C28: =COUNTBLANK(Tests!U$4:U1018) -> 4720
B30: Zone | C30: Nombre | D30: % | E30: Sans multifuites
B31: Nbre catégorie | C31: =IFERROR(__xludf.DUMMYFUNCTION("COUNTUNIQUE(Tests!N4:N1018)"),4.0) -> 4 | D31: NOK
B32: North | C32: =COUNTIFS(Tests!N4:N1018,B32, Tests!AU4:AU1018,"N") -> 932 | D32: =C32/C$34 -> 0.7023361
B33: South | C33: =COUNTIFS(Tests!N4:N1018,B33, Tests!AU4:AU1018,"N") -> 395 | D33: =C33/C$34 -> 0.2976639
B34: Somme | C34: =SUM(C32:C33) -> 1327
B35: Non renseigné | C35: =COUNTBLANK(Tests!N$4:N$821) -> 79
A37: N° | B37: Equipement | C37: Nombre | D37: % | E37: x (m) | F37: y (m) | G37: z (m) | H37: Associated types
B38: Nbre catégories | C38: =IFERROR(__xludf.DUMMYFUNCTION("COUNTUNIQUE(Tests!O4:O1018)"),37.0) -> 37 | H38: NOK
B39: {=SORT(UNIQUE('Leak conditions'!C2:C137))} -> Fixed Point 1 | C39: =COUNTIF(Tests!O$4:O1018,B39) -> 306 | D39: =C39/C$52 -> 0.17657242 | E39: =IFERROR(__xludf.DUMMYFUNCTION("JOIN("" | "", TRANSPOSE(UNIQUE(FILTER(Tests!R$4:R1018, Tests!O$4:O1018=B39))))"),"22,4 | 22,7 | 18,4") -> 22,4 | 22,7 | 18,4 | F39: =IFERROR(__xludf.DUMMYFUNCTION("JOIN("" | "", TRANSPOSE(UNIQUE(FILTER(Tests!S$4:S1018, Tests!O$4:O1018=B39))))"),"39,6 | 39,7 | 22,7 | 35") -> 39,6 | 39,7 | 22,7 | 35 | G39: =IFERROR(__xludf.DUMMYFUNCTION("JOIN("" | "", TRANSPOSE(UNIQUE(FILTER(Tests!T$4:T1018, Tests!O$4:O1018=B39))))"),"1,8 | 1,0 | | 1,1 | 0,45 | 22,7 | 1,9 | 1,09 | 1,02 | 6,15 | 1,82") -> 1,8 | 1,0 | | 1,1 | 0,45 | 22,7 | 1,9 | 1,09 | 1,02 | 6,15 | 1,82 | H39: =IFERROR(__xludf.DUMMYFUNCTION("JOIN("", "", TRANSPOSE(UNIQUE(FILTER(Tests!P$4:P1018, Tests!O$4:O1018=B39))))"),"Horizontal tubing, Vertical tubing, Vertical piping, Drilled Plug, Open Ended Line on 6 m mast") -> Horizontal tubing, Vertical tubing, Vertical piping, Drilled Plug, Open Ended Line on 6 m mast
B40: Fixed Point 2 | C40: =COUNTIF(Tests!O$4:O1018,B40) -> 215 | D40: =C40/C$52 -> 0.12406232 | E40: =IFERROR(__xludf.DUMMYFUNCTION("JOIN("" | "", TRANSPOSE(UNIQUE(FILTER(Tests!R$4:R1018, Tests!O$4:O1018=B40))))"),"21,4 | 21,7") -> 21,4 | 21,7 | F40: =IFERROR(__xludf.DUMMYFUNCTION("JOIN("" | "", TRANSPOSE(UNIQUE(FILTER(Tests!S$4:S1018, Tests!O$4:O1018=B40))))"),"39,3 | 39,6 | 39,5 | -39,5") -> 39,3 | 39,6 | 39,5 | -39,5 | G40: =IFERROR(__xludf.DUMMYFUNCTION("JOIN("" | "", TRANSPOSE(UNIQUE(FILTER(Tests!T$4:T1018, Tests!O$4:O1018=B40))))"),"1,2 | 1,3 | | 1,8 | 1,6 | 2,4 | 1,26 | 1,28 | 1,29 | 2,5") -> 1,2 | 1,3 | | 1,8 | 1,6 | 2,4 | 1,26 | 1,28 | 1,29 | 2,5 | H40: =IFERROR(__xludf.DUMMYFUNCTION("JOIN("", "", TRANSPOSE(UNIQUE(FILTER(Tests!P$4:P1018, Tests!O$4:O1018=B40))))"),"Vertical piping, Horizontal piping, Vertical tubing, High vertical piping, High Vertical piping, Vertical Piping 3"", Vertical Piping 1""") -> Vertical piping, Horizontal piping, Vertical tubing, High vertical piping, High Vertical piping, Vertical Piping 3", Vertical Piping 1"
A41: 0 | B41: Flare (6,5 m) | C41: =COUNTIF(Tests!O$4:O1018,B41) -> 87 | D41: =C41/C$52 -> 0.050201962 | E41: =IFERROR(__xludf.DUMMYFUNCTION("JOIN("" | "", TRANSPOSE(UNIQUE(FILTER(Tests!R$4:R1018, Tests!O$4:O1018=B41))))"),"(37,7,6,5) | 37 | 37,1") -> (37,7,6,5) | 37 | 37,1 | F41: =IFERROR(__xludf.DUMMYFUNCTION("JOIN("" | "", TRANSPOSE(UNIQUE(FILTER(Tests!S$4:S1018, Tests!O$4:O1018=B41))))")," | 7 | 6,9") -> | 7 | 6,9 | G41: =IFERROR(__xludf.DUMMYFUNCTION("JOIN("" | "", TRANSPOSE(UNIQUE(FILTER(Tests!T$4:T1018, Tests!O$4:O1018=B41))))")," | 6,5 | 7") -> | 6,5 | 7 | H41: =IFERROR(__xludf.DUMMYFUNCTION("JOIN("", "", TRANSPOSE(UNIQUE(FILTER(Tests!P$4:P1018, Tests!O$4:O1018=B41))))"),"Open ended line, Fin de ligne Ouverte, Open Ended Line") -> Open ended line, Fin de ligne Ouverte, Open Ended Line
A42: 0 | B42: Large Tank D1 | C42: =COUNTIF(Tests!O$4:O1018,B42) -> 145 | D42: =C42/C$52 -> 0.083669937 | E42: =IFERROR(__xludf.DUMMYFUNCTION("JOIN("" | "", TRANSPOSE(UNIQUE(FILTER(Tests!R$4:R1018, Tests!O$4:O1018=B42))))"),"(11,8,3) | 10,3 | 10 | 10,5 | 10,7 | 9 | 16") -> (11,8,3) | 10,3 | 10 | 10,5 | 10,7 | 9 | 16 | F42: =IFERROR(__xludf.DUMMYFUNCTION("JOIN("" | "", TRANSPOSE(UNIQUE(FILTER(Tests!S$4:S1018, Tests!O$4:O1018=B42))))")," | 7,8 | 11,7 | 7,9 | 10,9 | 8,1 | 8,5 | 4,5 | -11,7") -> | 7,8 | 11,7 | 7,9 | 10,9 | 8,1 | 8,5 | 4,5 | -11,7 | G42: =IFERROR(__xludf.DUMMYFUNCTION("JOIN("" | "", TRANSPOSE(UNIQUE(FILTER(Tests!T$4:T1018, Tests!O$4:O1018=B42))))")," | 3 | 0,4 | 3,2 | 0,5 | 1,8 | 1,4") -> | 3 | 0,4 | 3,2 | 0,5 | 1,8 | 1,4 | H42: =IFERROR(__xludf.DUMMYFUNCTION("JOIN("", "", TRANSPOSE(UNIQUE(FILTER(Tests!P$4:P1018, Tests!O$4:O1018=B42))))"),"Man hole, Trou d'homme, Vanne, Valve, Flange, Poteau le long paroi ouest du tank D1, Valve - Flex PA 8 mm, Valve - Flex PA 4 mm") -> Man hole, Trou d'homme, Vanne, Valve, Flange, Poteau le long paroi ouest du tank D1, Valve - Flex PA 8 mm, Valve - Flex PA 4 mm
A43: 1 | B43: Long Tank D3 | C43: =COUNTIF(Tests!O$4:O1018,B43) -> 72 | D43: =C43/C$52 -> 0.041546451 | E43: =IFERROR(__xludf.DUMMYFUNCTION("JOIN("" | "", TRANSPOSE(UNIQUE(FILTER(Tests!R$4:R1018, Tests!O$4:O1018=B43))))"),"(16,10,0,02) | 16 | 16,2 | 21,2 | 16,1 | 16,4") -> (16,10,0,02) | 16 | 16,2 | 21,2 | 16,1 | 16,4 | F43: =IFERROR(__xludf.DUMMYFUNCTION("JOIN("" | "", TRANSPOSE(UNIQUE(FILTER(Tests!S$4:S1018, Tests!O$4:O1018=B43))))")," | 10 | 9,3 | 9,6 | 8,7 | 10,4 | -9,6") -> | 10 | 9,3 | 9,6 | 8,7 | 10,4 | -9,6 | G43: =IFERROR(__xludf.DUMMYFUNCTION("JOIN("" | "", TRANSPOSE(UNIQUE(FILTER(Tests!T$4:T1018, Tests!O$4:O1018=B43))))")," | 0,02 | 0,01 | 0,1 | 2,4 | 0 | 0,44 | 0,4") -> | 0,02 | 0,01 | 0,1 | 2,4 | 0 | 0,44 | 0,4 | H43: =IFERROR(__xludf.DUMMYFUNCTION("JOIN("", "", TRANSPOSE(UNIQUE(FILTER(Tests!P$4:P1018, Tests!O$4:O1018=B43))))"),"Open ended line, Open Ended Line, Outlet valve, Open Ended Line - Flex PA 6 mm, Open Ended Line - Flex PA 4 mm") -> Open ended line, Open Ended Line, Outlet valve, Open Ended Line - Flex PA 6 mm, Open Ended Line - Flex PA 4 mm
...

Sheet Leak conditions
A1: Location | B1: ID | C1: Equipment | D1: Control Valve | E1: N° | F1: ID | G1: Leak Type / Location | H1: Leak Description | I1: Local X (m) | J1: Local Y (m) | K1: Local Z (m) | L1: N° | M1: ID | N1: Type and nominal size of orifice | O1: ID (mm) | P1: Tubing Color | Q1: Leak ID | S1: Equipment | U1: Control Valve | W1: Type and nominal size of orifice | X1: ID (mm)
A2: North | B2: N1 | C2: Mobile Valve 1 | D2: XOV401 | E2: 1 | F2: N1-1 | G2: Drilled Plug | H2: Mobile Valve 1 - Drilled Plug | I2: 11.6 | J2: -9.1 | K2: 0.68 | L2: 1 | M2: N1-1-1 | N2: Pierced cap 0,5 mm | O2: 0.5 | P2: - | Q2: N1-1/ID:0,5mm | S2: - | U2: - | W2: - | X2: -
A3: North | B3: N1 | C3: Mobile Valve 1 | D3: XOV401 | E3: 1 | F3: N1-1 | G3: Drilled Plug | H3: Mobile Valve 1 - Drilled Plug | I3: 11.6 | J3: -9.1 | K3: 0.68 | L3: 2 | M3: N1-1-2 | N3: Pierced cap 1 mm | O3: 1 | P3: - | Q3: N1-1/ID:1mm | S3: Mobile Valve 1 | U3: XOV401 | W3: Pierced cap 0,5 mm | X3: 0.5
A4: North | B4: N1 | C4: Mobile Valve 1 | D4: XOV401 | E4: 1 | F4: N1-1 | G4: Drilled Plug | H4: Mobile Valve 1 - Drilled Plug | I4: 11.6 | J4: -9.1 | K4: 0.68 | L4: 3 | M4: N1-1-3 | N4: Pierced cap 1,5 mm | O4: 1.5 | P4: - | Q4: N1-1/ID:1,5mm | S4: Pipe Rack | U4: XOV402 | W4: Pierced cap 1 mm | X4: 1
A5: North | B5: N1 | C5: Mobile Valve 1 | D5: XOV401 | E5: 1 | F5: N1-1 | G5: Drilled Plug | H5: Mobile Valve 1 - Drilled Plug | I5: 11.6 | J5: -9.1 | K5: 0.68 | L5: 4 | M5: N1-1-4 | N5: Pierced cap 2 mm | O5: 2 | P5: - | Q5: N1-1/ID:2mm | S5: Mobile Valves 3 | U5: FCV403A | W5: Pierced cap 1,5 mm | X5: 1.5
A6: North | B6: N1 | C6: Mobile Valve 1 | D6: XOV401 | E6: 1 | F6: N1-1 | G6: Drilled Plug | H6: Mobile Valve 1 - Drilled Plug | I6: 11.6 | J6: -9.1 | K6: 0.68 | L6: 5 | M6: N1-1-5 | N6: Pierced cap 2,5 mm | O6: 2.5 | P6: - | Q6: N1-1/ID:2,5mm | S6: Large Tank D1 | U6: FCV403B | W6: Pierced cap 2 mm | X6: 2
A7: North | B7: N1 | C7: Mobile Valve 1 | D7: XOV401 | E7: 1 | F7: N1-1 | G7: Drilled Plug | H7: Mobile Valve 1 - Drilled Plug | I7: 11.6 | J7: -9.1 | K7: 0.68 | L7: 6 | M7: N1-1-6 | N7: Pierced cap 3 mm | O7: 3 | P7: - | Q7: N1-1/ID:3mm | S7: Small Tank D2 | U7: FCV404 | W7: Pierced cap 2,5 mm | X7: 2.5
A8: North | B8: N1 | C8: Mobile Valve 1 | D8: XOV401 | E8: 1 | F8: N1-1 | G8: Drilled Plug | H8: Mobile Valve 1 - Drilled Plug | I8: 11.6 | J8: -9.1 | K8: 0.68 | L8: 7 | M8: N1-1-7 | N8: Pierced cap 4 mm | O8: 4 | P8: - | Q8: N1-1/ID:4mm | S8: Long Tank D3 | U8: FCV405 | W8: Pierced cap 3 mm | X8: 3
A9: North | B9: N1 | C9: Mobile Valve 1 | D9: XOV401 | E9: 1 | F9: N1-1 | G9: Drilled Plug | H9: Mobile Valve 1 - Drilled Plug | I9: 11.6 | J9: -9.1 | K9: 0.68 | L9: 8 | M9: N1-1-8 | N9: Pierced cap 5 mm | O9: 5 | P9: - | Q9: N1-1/ID:5mm | S9: Product Skid | U9: FCV406 | W9: Pierced cap 4 mm | X9: 4
A10: North | B10: N1 | C10: Mobile Valve 1 | D10: XOV401 | E10: 2 | F10: N1-2 | G10: Mobile flange | H10: Mobile Valve 1 - Mobile flange | I10: - | J10: - | K10: - | L10: 1 | M10: N1-2-1 | N10: Flange space - | O10: - | P10: - | Q10: N1-2/ID:-mm | S10: RPB | U10: FCV407 | W10: Pierced cap 5 mm | X10: 5
A11: North | B11: N2 | C11: Pipe Rack | D11: XOV402 | E11: 1 | F11: N2-1 | G11: Corroded Pipe | H11: Pipe Rack - Corroded Pipe | I11: 24.4 | J11: -7.7 | K11: 0.57 | L11: 1 | M11: N2-1-1 | N11: Hole 10 mm | O11: 10 | P11: - | Q11: N2-1/ID:10mm | S11: Scrubber | U11: FCV408 | W11: Hole 10 mm | X11: 10
A12: North | B12: N2 | C12: Pipe Rack | D12: XOV402 | E12: 2 | F12: N2-2 | G12: Drilled Plug | H12: Pipe Rack - Drilled Plug | I12: 24.4 | J12: -7.5 | K12: 0.57 | L12: 1 | M12: N2-2-1 | N12: Pierced cap 0,5 mm | O12: 0.5 | P12: - | Q12: N2-2/ID:0,5mm | S12: Well Head | U12: FCV409 | W12: Flex PA 3 mm | X12: 1.8
A13: North | B13: N2 | C13: Pipe Rack | D13: XOV402 | E13: 2 | F13: N2-2 | G13: Drilled Plug | H13: Pipe Rack - Drilled Plug | I13: 24.4 | J13: -7.5 | K13: 0.57 | L13: 2 | M13: N2-2-2 | N13: Pierced cap 1 mm | O13: 1 | P13: - | Q13: N2-2/ID:1mm | S13: Flare (6,5 m) | U13: FCV410 | W13: Flex PA 4 mm | X13: 2.7
A14: North | B14: N2 | C14: Pipe Rack | D14: XOV402 | E14: 2 | F14: N2-2 | G14: Drilled Plug | H14: Pipe Rack - Drilled Plug | I14: 24.4 | J14: -7.5 | K14: 0.57 | L14: 3 | M14: N2-2-3 | N14: Pierced cap 1,5 mm | O14: 1.5 | P14: - | Q14: N2-2/ID:1,5mm | S14: Fixed Point 1 | U14: FCV411 | W14: Flex PA 6 mm | X14: 4
A15: North | B15: N2 | C15: Pipe Rack | D15: XOV402 | E15: 2 | F15: N2-2 | G15: Drilled Plug | H15: Pipe Rack - Drilled Plug | I15: 24.4 | J15: -7.5 | K15: 0.57 | L15: 4 | M15: N2-2-4 | N15: Pierced cap 2 mm | O15: 2 | P15: - | Q15: N2-2/ID:2mm | S15: Fixed Point 2 | U15: FCV005/010 | W15: Flex PA 8 mm | X15: 6
A16: North | B16: N2 | C16: Pipe Rack | D16: XOV402 | E16: 2 | F16: N2-2 | G16: Drilled Plug | H16: Pipe Rack - Drilled Plug | I16: 24.4 | J16: -7.5 | K16: 0.57 | L16: 5 | M16: N2-2-5 | N16: Pierced cap 2,5 mm | O16: 2.5 | P16: - | Q16: N2-2/ID:2,5mm | U16: FCV020 | W16: Flex PA 10 mm | X16: 8
A17: North | B17: N2 | C17: Pipe Rack | D17: XOV402 | E17: 2 | F17: N2-2 | G17: Drilled Plug | H17: Pipe Rack - Drilled Plug | I17: 24.4 | J17: -7.5 | K17: 0.57 | L17: 6 | M17: N2-2-6 | N17: Pierced cap 3 mm | O17: 3 | P17: - | Q17: N2-2/ID:3mm | U17: FCV010/XOV402 | W17: Flex PA 12 mm | X17: 10
A18: North | B18: N2 | C18: Pipe Rack | D18: XOV402 | E18: 2 | F18: N2-2 | G18: Drilled Plug | H18: Pipe Rack - Drilled Plug | I18: 24.4 | J18: -7.5 | K18: 0.57 | L18: 7 | M18: N2-2-7 | N18: Pierced cap 4 mm | O18: 4 | P18: - | Q18: N2-2/ID:4mm | W18: Tubing 6 mm | X18: 4
A19: North | B19: N2 | C19: Pipe Rack | D19: XOV402 | E19: 2 | F19: N2-2 | G19: Drilled Plug | H19: Pipe Rack - Drilled Plug | I19: 24.4 | J19: -7.5 | K19: 0.57 | L19: 8 | M19: N2-2-8 | N19: Pierced cap 5 mm | O19: 5 | P19: - | Q19: N2-2/ID:5mm | W19: Tubing 8 mm | X19: 6
A20: North | B20: N2 | C20: Pipe Rack | D20: FCV403A/B | E20: 3 | F20: N2-3 | G20: Corroded Pipe | H20: Pipe Rack - Corroded Pipe | I20: 24.4 | J20: -7.7 | K20: 0.57 | L20: 1 | M20: N2-3-1 | N20: Hole 10 mm | O20: 10 | P20: - | Q20: N2-3/ID:10mm | W20: Tubing 10 mm | X20: 8
A21: North | B21: N2 | C21: Pipe Rack | D21: FCV403A/B | E21: 4 | F21: N2-4 | G21: Drilled Plug | H21: Pipe Rack - Drilled Plug | I21: 24.4 | J21: -7.5 | K21: 0.57 | L21: 1 | M21: N2-4-1 | N21: Pierced cap 0,5 mm | O21: 0.5 | P21: - | Q21: N2-4/ID:0,5mm | W21: Tubing 3/4" | X21: 15.75
A22: North | B22: N2 | C22: Pipe Rack | D22: FCV403A/B | E22: 4 | F22: N2-4 | G22: Drilled Plug | H22: Pipe Rack - Drilled Plug | I22: 24.4 | J22: -7.5 | K22: 0.57 | L22: 2 | M22: N2-4-2 | N22: Pierced cap 1 mm | O22: 1 | P22: - | Q22: N2-4/ID:1mm | W22: Tubing 1" | X22: 22.1
A23: North | B23: N2 | C23: Pipe Rack | D23: FCV403A/B | E23: 4 | F23: N2-4 | G23: Drilled Plug | H23: Pipe Rack - Drilled Plug | I23: 24.4 | J23: -7.5 | K23: 0.57 | L23: 3 | M23: N2-4-3 | N23: Pierced cap 1,5 mm | O23: 1.5 | P23: - | Q23: N2-4/ID:1,5mm | W23: Piping 1" | X23: 26.6
A24: North | B24: N2 | C24: Pipe Rack | D24: FCV403A/B | E24: 4 | F24: N2-4 | G24: Drilled Plug | H24: Pipe Rack - Drilled Plug | I24: 24.4 | J24: -7.5 | K24: 0.57 | L24: 4 | M24: N2-4-4 | N24: Pierced cap 2 mm | O24: 2 | P24: - | Q24: N2-4/ID:2mm | W24: Piping 2" | X24: 52.5
A25: North | B25: N2 | C25: Pipe Rack | D25: FCV403A/B | E25: 4 | F25: N2-4 | G25: Drilled Plug | H25: Pipe Rack - Drilled Plug | I25: 24.4 | J25: -7.5 | K25: 0.57 | L25: 5 | M25: N2-4-5 | N25: Pierced cap 2,5 mm | O25: 2.5 | P25: - | Q25: N2-4/ID:2,5mm | W25: Piping 3" | X25: 77.9
A26: North | B26: N2 | C26: Pipe Rack | D26: FCV403A/B | E26: 4 | F26: N2-4 | G26: Drilled Plug | H26: Pipe Rack - Drilled Plug | I26: 24.4 | J26: -7.5 | K26: 0.57 | L26: 6 | M26: N2-4-6 | N26: Pierced cap 3 mm | O26: 3 | P26: - | Q26: N2-4/ID:3mm | W26: Piping 4" | X26: 102.3
A27: North | B27: N2 | C27: Pipe Rack | D27: FCV403A/B | E27: 4 | F27: N2-4 | G27: Drilled Plug | H27: Pipe Rack - Drilled Plug | I27: 24.4 | J27: -7.5 | K27: 0.57 | L27: 7 | M27: N2-4-7 | N27: Pierced cap 4 mm | O27: 4 | P27: - | Q27: N2-4/ID:4mm
A28: North | B28: N2 | C28: Pipe Rack | D28: FCV403A/B | E28: 4 | F28: N2-4 | G28: Drilled Plug | H28: Pipe Rack - Drilled Plug | I28: 24.4 | J28: -7.5 | K28: 0.57 | L28: 8 | M28: N2-4-8 | N28: Pierced cap 5 mm | O28: 5 | P28: - | Q28: N2-4/ID:5mm
A29: North | B29: N3 | C29: Mobile Valves 3 | D29: FCV403A | E29: 1 | F29: N3-1 | G29: Drilled Plug | H29: Mobile Valves 3 - Drilled Plug | I29: - | J29: - | K29: 0.64 | L29: 1 | M29: N3-1-1 | N29: Pierced cap 0,5 mm | O29: 0.5 | P29: - | Q29: N3-1/ID:0,5mm
A30: North | B30: N3 | C30: Mobile Valves 3 | D30: FCV403A | E30: 1 | F30: N3-1 | G30: Drilled Plug | H30: Mobile Valves 3 - Drilled Plug | I30: - | J30: - | K30: 0.64 | L30: 2 | M30: N3-1-2 | N30: Pierced cap 1 mm | O30: 1 | P30: - | Q30: N3-1/ID:1mm
A31: North | B31: N3 | C31: Mobile Valves 3 | D31: FCV403A | E31: 1 | F31: N3-1 | G31: Drilled Plug | H31: Mobile Valves 3 - Drilled Plug | I31: - | J31: - | K31: 0.64 | L31: 3 | M31: N3-1-3 | N31: Pierced cap 1,5 mm | O31: 1.5 | P31: - | Q31: N3-1/ID:1,5mm
A32: North | B32: N3 | C32: Mobile Valves 3 | D32: FCV403A | E32: 1 | F32: N3-1 | G32: Drilled Plug | H32: Mobile Valves 3 - Drilled Plug | I32: - | J32: - | K32: 0.64 | L32: 4 | M32: N3-1-4 | N32: Pierced cap 2 mm | O32: 2 | P32: - | Q32: N3-1/ID:2mm
A33: North | B33: N3 | C33: Mobile Valves 3 | D33: FCV403A | E33: 1 | F33: N3-1 | G33: Drilled Plug | H33: Mobile Valves 3 - Drilled Plug | I33: - | J33: - | K33: 0.64 | L33: 5 | M33: N3-1-5 | N33: Pierced cap 2,5 mm | O33: 2.5 | P33: - | Q33: N3-1/ID:2,5mm
A34: North | B34: N3 | C34: Mobile Valves 3 | D34: FCV403A | E34: 1 | F34: N3-1 | G34: Drilled Plug | H34: Mobile Valves 3 - Drilled Plug | I34: - | J34: - | K34: 0.64 | L34: 6 | M34: N3-1-6 | N34: Pierced cap 3 mm | O34: 3 | P34: - | Q34: N3-1/ID:3mm
A35: North | B35: N3 | C35: Mobile Valves 3 | D35: FCV403A | E35: 1 | F35: N3-1 | G35: Drilled Plug | H35: Mobile Valves 3 - Drilled Plug | I35: - | J35: - | K35: 0.64 | L35: 7 | M35: N3-1-7 | N35: Pierced cap 4 mm | O35: 4 | P35: - | Q35: N3-1/ID:4mm
A36: North | B36: N3 | C36: Mobile Valves 3 | D36: FCV403A | E36: 1 | F36: N3-1 | G36: Drilled Plug | H36: Mobile Valves 3 - Drilled Plug | I36: - | J36: - | K36: 0.64 | L36: 8 | M36: N3-1-8 | N36: Pierced cap 5 mm | O36: 5 | P36: - | Q36: N3-1/ID:5mm
A37: North | B37: N3 | C37: Mobile Valves 3 | D37: FCV403A | E37: 2 | F37: N3-2 | G37: Mobile flange | H37: Mobile Valves 3 - Mobile flange | I37: - | J37: - | K37: - | L37: 1 | M37: N3-2-1 | N37: Flange space - | O37: - | P37: - | Q37: N3-2/ID:-mm
A38: North | B38: N3 | C38: Mobile Valves 3 | D38: FCV403B | E38: 3 | F38: N3-3 | G38: Drilled Plug | H38: Mobile Valves 3 - Drilled Plug | I38: - | J38: - | K38: 0.55 | L38: 1 | M38: N3-3-1 | N38: Pierced cap 0,5 mm | O38: 0.5 | P38: - | Q38: N3-3/ID:0,5mm
A39: North | B39: N3 | C39: Mobile Valves 3 | D39: FCV403B | E39: 3 | F39: N3-3 | G39: Drilled Plug | H39: Mobile Valves 3 - Drilled Plug | I39: - | J39: - | K39: 0.55 | L39: 2 | M39: N3-3-2 | N39: Pierced cap 1 mm | O39: 1 | P39: - | Q39: N3-3/ID:1mm
A40: North | B40: N3 | C40: Mobile Valves 3 | D40: FCV403B | E40: 3 | F40: N3-3 | G40: Drilled Plug | H40: Mobile Valves 3 - Drilled Plug | I40: - | J40: - | K40: 0.55 | L40: 3 | M40: N3-3-3 | N40: Pierced cap 1,5 mm | O40: 1.5 | P40: - | Q40: N3-3/ID:1,5mm
...

Sheet Statistics
A1: Code couleur des tests
A2: Manque d'information | D2: Conditions adaptées
A3: Non détecté | D3: Débit | E3: >1 g/s
A4: Localisé | D4: Zone
A5: Détecté | D5: Multifuites | E5: NON
A6: Emerge | D6: Purges | E6: NON
A8: GLOBAL
A9: Total | B9: =COUNT(Tests!C$4:C989) -> 2259 | E9: Conditions adaptées | I9: Détection | M9: Localisation | Q9: Nord | S9: Sud | W9: 0-1 (g/s) | Y9: 1-10 (g/s) | AA9: 10+ (g/s) | AD9: Erreur | AE9: Nord | AF9: Sud
A10: Purges | B10: =IFERROR(__xludf.DUMMYFUNCTION("COUNT(FILTER(Tests!C$4:C989, FIND(""TADI's purge"", Tests!P$4:P989)))"),175.0) -> 175 | E10: Test | F10: % | I10: Test | J10: % | M10: Test | N10: % | Q10: Test | R10: % | S10: Test | T10: % | W10: Test | X10: % | Y10: Test | Z10: % | AA10: Test | AB10: % | AD10: Localisés | AE10: =IFERROR(__xludf.DUMMYFUNCTION("COUNT(FILTER(Tests!C$4:C989, Tests!BW$4:BW989>0, Tests!N$4:N989=""North""))"),467.0) -> 467 | AF10: =IFERROR(__xludf.DUMMYFUNCTION("COUNT(FILTER(Tests!C$4:C989, Tests!BW$4:BW989>0, Tests!N$4:N989=""South""))"),227.0) -> 227
D11: Détectés | E11: =IFERROR(__xludf.DUMMYFUNCTION("COUNT(FILTER(Tests!C$4:C989, Tests!BS$4:BS989>0, Tests!U$4:U989>=1, Tests!AU$4:AU989=""N"", Tests!N$4:N989=""North""))"),398.0) -> 398 | F11: =E11/E13 -> 0.52162516 | H11: Détectés | I11: =IFERROR(__xludf.DUMMYFUNCTION("COUNT(FILTER(Tests!C$4:C989, Tests!BS$4:BS989>0))"),971.0) -> 971 | J11: =I11/I13 -> 0.4595362 | L11: Localisés | M11: =IFERROR(__xludf.DUMMYFUNCTION("COUNT(FILTER(Tests!C$4:C989, Tests!BS$4:BS989>0, Tests!BW$4:BW989>0))"),674.0) -> 674 | N11: =M11/M13 -> 0.69484536 | P11: Détectés | Q11: =IFERROR(__xludf.DUMMYFUNCTION("COUNT(FILTER(Tests!C$4:C989, Tests!BS$4:BS989>0, Tests!N$4:N989=""North""))"),654.0) -> 654 | R11: =Q11/Q13 -> 0.48769575 | S11: =IFERROR(__xludf.DUMMYFUNCTION("COUNT(FILTER(Tests!C$4:C989, Tests!BS$4:BS989>0, Tests!N$4:N989=""South""))"),314.0) -> 314 | T11: =S11/S13 -> 0.45906433 | V11: Détectés | W11: =IFERROR(__xludf.DUMMYFUNCTION("COUNT(FILTER(Tests!C$4:C989, Tests!BS$4:BS989>0, Tests!U$4:U989<1))"),207.0) -> 207 | X11: =W11/W13 -> 0.345 | Y11: =IFERROR(__xludf.DUMMYFUNCTION("COUNT(FILTER(Tests!C$4:C989, Tests!BS$4:BS989>0, Tests!U$4:U989>=1, Tests!U$4:U989<10))"),578.0) -> 578 | Z11: =Y11/Y13 -> 0.49956785 | AA11: =IFERROR(__xludf.DUMMYFUNCTION("COUNT(FILTER(Tests!C$4:C989, Tests!BS$4:BS989>0, Tests!U$4:U989>=10))"),186.0) -> 186 | AB11: =AA11/AA13 -> 0.44711538 | AD11: Moyenne (m) | AE11: =IFERROR(__xludf.DUMMYFUNCTION("AVERAGE(FILTER(Tests!$BY$4:$BY989, Tests!$BW$4:$BW989>0, Tests!$N$4:$N989=""North""))"),11.171644797227279) -> 11.171645 | AF11: =IFERROR(__xludf.DUMMYFUNCTION("AVERAGE(FILTER(Tests!$BY$4:$BY989, Tests!$BW$4:$BW989>0, Tests!$N$4:$N989=""South""))"),16.522700849237197) -> 16.522701
D12: Non détectés | E12: =IFERROR(__xludf.DUMMYFUNCTION("COUNT(FILTER(Tests!C$4:C989, Tests!BS$4:BS989=0, Tests!U$4:U989>=1, Tests!AU$4:AU989=""N"", Tests!N$4:N989=""North""))"),365.0) -> 365 | F12: =E12/E13 -> 0.47837484 | H12: Non détectés | I12: =IFERROR(__xludf.DUMMYFUNCTION("COUNT(FILTER(Tests!C$4:C989, Tests!BS$4:BS989=0, Tests!BS$4:BS989<>""""))"),1142.0) -> 1142 | J12: =I12/I13 -> 0.5404638 | L12: Non localisés | M12: =IFERROR(__xludf.DUMMYFUNCTION("COUNT(FILTER(Tests!C$4:C989, Tests!BS$4:BS989>0, Tests!BW$4:BW989=""""))"),296.0) -> 296 | N12: =M12/M13 -> 0.30515464 | P12: Non détectés | Q12: =IFERROR(__xludf.DUMMYFUNCTION("COUNT(FILTER(Tests!C$4:C989, Tests!BS$4:BS989=0, Tests!BS$4:BS989<>"""", Tests!N$4:N989=""North""))"),687.0) -> 687 | R12: =Q12/Q13 -> 0.51230425 | S12: =IFERROR(__xludf.DUMMYFUNCTION("COUNT(FILTER(Tests!C$4:C989, Tests!BS$4:BS989=0, Tests!BS$4:BS989<>"""", Tests!N$4:N989=""South""))"),370.0) -> 370 | T12: =S12/S13 -> 0.54093567 | V12: Non détectés | W12: =IFERROR(__xludf.DUMMYFUNCTION("COUNT(FILTER(Tests!C$4:C989, Tests!BS$4:BS989=0, Tests!BS$4:BS989<>"""", Tests!U$4:U989<1))"),393.0) -> 393 | X12: =W12/W13 -> 0.655 | Y12: =IFERROR(__xludf.DUMMYFUNCTION("COUNT(FILTER(Tests!C$4:C989, Tests!BS$4:BS989=0, Tests!U$4:U989>=1, Tests!U$4:U989<10))"),579.0) -> 579 | Z12: =Y12/Y13 -> 0.50043215 | AA12: =IFERROR(__xludf.DUMMYFUNCTION("COUNT(FILTER(Tests!C$4:C989, Tests!BS$4:BS989=0, Tests!BS$4:BS989<>"""", Tests!U$4:U989>=10))"),230.0) -> 230 | AB12: =AA12/AA13 -> 0.55288462 | AD12: Médiane (m) | AE12: =IFERROR(__xludf.DUMMYFUNCTION("MEDIAN(FILTER(Tests!BY$4:BY989, Tests!BW$4:BW989>0, Tests!N$4:N989=""North""))"),8.80017641102833) -> 8.8001764 | AF12: =IFERROR(__xludf.DUMMYFUNCTION("MEDIAN(FILTER(Tests!BY$4:BY989, Tests!BW$4:BW989>0, Tests!N$4:N989=""South""))"),13.50408751514879) -> 13.504088
D13: Total | E13: =SUM(E11:E12) -> 763 | H13: Total | I13: =SUM(I11:I12) -> 2113 | L13: Total | M13: =M11+M12 -> 970 | P13: Total | Q13: =Q11+Q12 -> 1341 | S13: =S11+S12 -> 684 | V13: Total | W13: =W11+W12 -> 600 | Y13: =Y11+Y12 -> 1157 | AA13: =AA11+AA12 -> 416 | AD13: Maximum (m) | AE13: =IFERROR(__xludf.DUMMYFUNCTION("MAX(FILTER(Tests!BY$4:BY989, Tests!BW$4:BW989>0, Tests!N$4:N989=""North""))"),45.15152267642809) -> 45.151523 | AF13: =IFERROR(__xludf.DUMMYFUNCTION("MAX(FILTER(Tests!BY$4:BY989, Tests!BW$4:BW989>0, Tests!N$4:N989=""South""))"),50.307554104726655) -> 50.307554
D14: Non adaptés | E14: =B9-E13 -> 1496 | H14: Non renseignés | I14: =B9-I13 -> 146 | AD14: Minimum (m) | AE14: =IFERROR(__xludf.DUMMYFUNCTION("MIN(FILTER(Tests!BY$4:BY989, Tests!BW$4:BW989>0, Tests!N$4:N989=""North""))"),0.2699999999999996) -> 0.27 | AF14: =IFERROR(__xludf.DUMMYFUNCTION("MIN(FILTER(Tests!BY$4:BY989, Tests!BW$4:BW989>0, Tests!N$4:N989=""South""))"),0.5099019513592787) -> 0.50990195
A17: Tests
A18: Date début | B18: 45292 | E18: Q>1 & Fuite unique | I18: Détection | M18: Localisation | Q18: Nord | S18: Sud | W18: 0-1 (g/s) | Y18: 1-10 (g/s) | AA18: 10+ (g/s) | AD18: Erreur | AE18: Nord | AF18: Sud | AH18: Distance mini | AI18: Nord | AJ18: Sud
A19: Date fin | B19: 45657 | E19: Test | F19: % | I19: Test | J19: % | M19: Test | N19: % | Q19: Test | R19: % | S19: Test | T19: % | W19: Test | X19: % | Y19: Test | Z19: % | AA19: Test | AB19: % | AD19: Localisés | AE19: =IFERROR(__xludf.DUMMYFUNCTION("COUNT(FILTER(Tests!C$4:C989, Tests!C$4:C989>=B18, Tests!C$4:C989<=B19, Tests!BW$4:BW989>0, Tests!N$4:N989=""North""))"),159.0) -> 159 | AF19: =IFERROR(__xludf.DUMMYFUNCTION("COUNT(FILTER(Tests!C$4:C989, Tests!C$4:C989>=B18, Tests!C$4:C989<=$B$19, Tests!BW$4:BW989>0, Tests!N$4:N989=""South""))"),116.0) -> 116 | AH19: Localisés | AI19: =IFERROR(__xludf.DUMMYFUNCTION("COUNT(FILTER(Tests!C$4:C989, Tests!C$4:C989>=B18, Tests!C$4:C989<=B19, Tests!BW$4:BW989>0, Tests!N$4:N989=""North""))"),159.0) -> 159 | AJ19: =IFERROR(__xludf.DUMMYFUNCTION("COUNT(FILTER(Tests!C$4:C989, Tests!C$4:C989>=B18, Tests!C$4:C989<=B19, Tests!BW$4:BW989>0, Tests!N$4:N989=""South""))"),116.0) -> 116
A20: Total | B20: =IFERROR(__xludf.DUMMYFUNCTION("COUNT(FILTER(Tests!C$4:C989, Tests!C$4:C989>=$B18, Tests!C$4:C989<=$B19))"),526.0) -> 526 | D20: Détectés | E20: =IFERROR(__xludf.DUMMYFUNCTION("COUNT(FILTER(Tests!C$4:C989, Tests!C$4:C989>=$B18, Tests!C$4:C989<=$B19, Tests!BS$4:BS989>0, Tests!U$4:U989>=1, Tests!AU$4:AU989<>""Y""))"),144.0) -> 144 | F20: =E20/E22 -> 0.59751037 | H20: Détectés | I20: =IFERROR(__xludf.DUMMYFUNCTION("COUNT(FILTER(Tests!C$4:C989, Tests!C$4:C989>=$B18, Tests!C$4:C989<=$B19, Tests!BS$4:BS989>0))"),276.0) -> 276 | J20: =I20/I22 -> 0.52571429 | L20: Localisés | M20: =IFERROR(__xludf.DUMMYFUNCTION("COUNT(FILTER(Tests!C$4:C989, Tests!C$4:C989>=B18, Tests!C$4:C989<=B19, Tests!BS$4:BS989>0, Tests!BW$4:BW989>0))"),276.0) -> 276 | N20: =M20/M22 -> 1 | P20: Détectés | Q20: =IFERROR(__xludf.DUMMYFUNCTION("COUNT(FILTER(Tests!C$4:C989, Tests!C$4:C989>=$B18, Tests!C$4:C989<=$B19, Tests!BS$4:BS989>0, Tests!N$4:N989=""North""))"),158.0) -> 158 | R20: =Q20/Q22 -> 0.48765432 | S20: =IFERROR(__xludf.DUMMYFUNCTION("COUNT(FILTER(Tests!C$4:C989, Tests!C$4:C989>=$B18, Tests!C$4:C989<=$B19, Tests!BS$4:BS989>0, Tests!N$4:N989=""South""))"),115.0) -> 115 | T20: =S20/S22 -> 0.58375635 | V20: Détectés | W20: =IFERROR(__xludf.DUMMYFUNCTION("COUNT(FILTER(Tests!C$4:C989, Tests!C$4:C989>=$B18, Tests!C$4:C989<=$B19, Tests!BS$4:BS989>0, Tests!AT$4:AT989=""0-1""))"),41.0) -> 41 | X20: =W20/W22 -> 0.31538462 | Y20: =IFERROR(__xludf.DUMMYFUNCTION("COUNT(FILTER(Tests!C$4:C989, Tests!C$4:C989>=$B18, Tests!C$4:C989<=$B19, Tests!BS$4:BS989>0, Tests!AT$4:AT989=""1-10""))"),110.0) -> 110 | Z20: =Y20/Y22 -> 0.6626506 | AA20: =IFERROR(__xludf.DUMMYFUNCTION("COUNT(FILTER(Tests!C$4:C989, Tests!C$4:C989>=$B18, Tests!C$4:C989<=$B19, Tests!BS$4:BS989>0, Tests!AT$4:AT989=""10+""))"),14.0) -> 14 | AB20: =AA20/AA22 -> 0.58333333 | AD20: Moyenne (m) | AE20: =IFERROR(__xludf.DUMMYFUNCTION("AVERAGE(FILTER(Tests!$BY$4:$BY989, Tests!$C$4:$C989>=$B$18, Tests!$C$4:$C989<=$B$19, Tests!$BW$4:$BW989>0, Tests!$N$4:$N989=""North""))"),15.756257124725217) -> 15.756257 | AF20: =IFERROR(__xludf.DUMMYFUNCTION("AVERAGE(FILTER(Tests!$BY$4:$BY989, Tests!$C$4:$C989>=$B$18, Tests!$C$4:$C989<=$B$19, Tests!$BW$4:$BW989>0, Tests!$N$4:$N989=""South""))"),16.552055020915496) -> 16.552055 | AH20: Maximum (m) | AI20: =IFERROR(__xludf.DUMMYFUNCTION("MIN(FILTER(Tests!$BT$4:$BT989, Tests!$C$4:$C989>=$B$18, Tests!$C$4:$C989<=$B$19, Tests!$BW$4:$BW989>0, Tests!$N$4:$N989=""North""))"),0.0) -> 0 | AJ20: =IFERROR(__xludf.DUMMYFUNCTION("MIN(FILTER(Tests!$BT$4:$BT989, Tests!$C$4:$C989>=$B$18, Tests!$C$4:$C989<=$B$19, Tests!$BW$4:$BW989>0, Tests!$N$4:$N989=""South""))"),0.0) -> 0
A21: Purges | B21: =IFERROR(__xludf.DUMMYFUNCTION("COUNT(FILTER(Tests!C$4:C989, Tests!C$4:C989>=$B18, Tests!C$4:C989<=$B19, FIND(""TADI's purge"", Tests!P$4:P989)))"),56.0) -> 56 | D21: Non détectés | E21: =IFERROR(__xludf.DUMMYFUNCTION("COUNT(FILTER(Tests!C$4:C989, Tests!C$4:C989>=$B18, Tests!C$4:C989<=$B19, Tests!BS$4:BS989=0, Tests!BS$4:BS989<>"""", Tests!U$4:U989>=1, Tests!AU$4:AU989<>""Y""))"),97.0) -> 97 | F21: =E21/E22 -> 0.40248963 | H21: Non détectés | I21: =IFERROR(__xludf.DUMMYFUNCTION("COUNT(FILTER(Tests!C$4:C989, Tests!C$4:C989>=$B18, Tests!C$4:C989<=$B19, Tests!BS$4:BS989=0, Tests!BS$4:BS989<>""""))"),249.0) -> 249 | J21: =I21/I22 -> 0.47428571 | L21: Non localisés | M21: =IFERROR(__xludf.DUMMYFUNCTION("COUNT(FILTER(Tests!C$4:C989, Tests!C$4:C989>=B18, Tests!C$4:C989<=B19, Tests!BS$4:BS989>0, Tests!BW$4:BW989=""""))"),0.0) -> 0 | N21: =M21/M22 -> 0 | P21: Non détectés | Q21: =IFERROR(__xludf.DUMMYFUNCTION("COUNT(FILTER(Tests!C$4:C989, Tests!C$4:C989>=$B18, Tests!C$4:C989<=$B19, Tests!BS$4:BS989=0, Tests!BS$4:BS989<>"""", Tests!N$4:N989=""North""))"),166.0) -> 166 | R21: =Q21/Q22 -> 0.51234568 | S21: =IFERROR(__xludf.DUMMYFUNCTION("COUNT(FILTER(Tests!C$4:C989, Tests!C$4:C989>=$B18, Tests!C$4:C989<=$B19, Tests!BS$4:BS989=0, Tests!BS$4:BS989<>"""", Tests!N$4:N989=""South""))"),82.0) -> 82 | T21: =S21/S22 -> 0.41624365 | V21: Non détectés | W21: =IFERROR(__xludf.DUMMYFUNCTION("COUNT(FILTER(Tests!C$4:C989, Tests!C$4:C989>=$B18, Tests!C$4:C989<=$B19, Tests!BS$4:BS989=0, Tests!BS$4:BS989<>"""", Tests!AT$4:AT989=""0-1""))"),89.0) -> 89 | X21: =W21/W22 -> 0.68461538 | Y21: =IFERROR(__xludf.DUMMYFUNCTION("COUNT(FILTER(Tests!C$4:C989, Tests!C$4:C989>=$B18, Tests!C$4:C989<=$B19, Tests!BS$4:BS989=0, Tests!BS$4:BS989<>"""", Tests!AT$4:AT989=""1-10""))"),56.0) -> 56 | Z21: =Y21/Y22 -> 0.3373494 | AA21: =IFERROR(__xludf.DUMMYFUNCTION("COUNT(FILTER(Tests!C$4:C989, Tests!C$4:C989>=$B18, Tests!C$4:C989<=$B19, Tests!BS$4:BS989=0, Tests!BS$4:BS989<>"""", Tests!AT$4:AT989=""10+""))"),10.0) -> 10 | AB21: =AA21/AA22 -> 0.41666667 | AD21: Médiane (m) | AE21: =IFERROR(__xludf.DUMMYFUNCTION("MEDIAN(FILTER(Tests!BY$4:BY989, Tests!C$4:C989>=$B$18, Tests!C$4:C989<=$B$19, Tests!BW$4:BW989>0, Tests!N$4:N989=""North""))"),14.207744367069674) -> 14.207744 | AF21: =IFERROR(__xludf.DUMMYFUNCTION("MEDIAN(FILTER(Tests!BY$4:BY989, Tests!C$4:C989>=$B$18, Tests!C$4:C989<=$B$19, Tests!BW$4:BW989>0, Tests!N$4:N989=""South""))"),9.773937244620209) -> 9.7739372 | AH21: Minimum (m) | AI21: =IFERROR(__xludf.DUMMYFUNCTION("MIN(FILTER(Tests!$BS$4:$BS989, Tests!$C$4:$C989>=$B$18, Tests!$C$4:$C989<=$B$19, Tests!$BW$4:$BW989>0, Tests!$N$4:$N989=""North""))"),0.0) -> 0 | AJ21: =IFERROR(__xludf.DUMMYFUNCTION("MIN(FILTER(Tests!$BS$4:$BS989, Tests!$C$4:$C989>=$B$18, Tests!$C$4:$C989<=$B$19, Tests!$BW$4:$BW989>0, Tests!$N$4:$N989=""South""))"),0.0) -> 0
D22: Total | E22: =SUM(E20:E21) -> 241 | H22: Total | I22: =SUM(I20:I21) -> 525 | L22: Total | M22: =M20+M21 -> 276 | P22: Total | Q22: =Q20+Q21 -> 324 | S22: =S20+S21 -> 197 | V22: Total | W22: =W20+W21 -> 130 | Y22: =Y20+Y21 -> 166 | AA22: =AA20+AA21 -> 24 | AD22: Maximum (m) | AE22: =IFERROR(__xludf.DUMMYFUNCTION("MAX(FILTER(Tests!BY$4:BY989, Tests!C$4:C989>=$B$18, Tests!C$4:C989<=$B$19, Tests!BW$4:BW989>0, Tests!N$4:N989=""North""))"),45.15152267642809) -> 45.151523 | AF22: =IFERROR(__xludf.DUMMYFUNCTION("MAX(FILTER(Tests!BY$4:BY989, Tests!C$4:C989>=$B$18, Tests!C$4:C989<=$B$19, Tests!BW$4:BW989>0, Tests!N$4:N989=""South""))"),50.307554104726655) -> 50.307554
D23: Non adaptés | E23: =B$20-E22 -> 285 | H23: Non renseignés | I23: =B20-I22 -> 1 | AD23: Minimum (m) | AE23: =IFERROR(__xludf.DUMMYFUNCTION("MIN(FILTER(Tests!BY$4:BY989, Tests!C$4:C989>=$B$18, Tests!C$4:C989<=$B$19, Tests!BW$4:BW989>0, Tests!N$4:N989=""North""))"),0.9848857801796103) -> 0.98488578 | AF23: =IFERROR(__xludf.DUMMYFUNCTION("MIN(FILTER(Tests!BY$4:BY989, Tests!C$4:C989>=$B$18, Tests!C$4:C989<=$B$19, Tests!BW$4:BW989>0, Tests!N$4:N989=""South""))"),3.0016662039607267) -> 3.0016662
E25: Q>0,5 & Nord & Fuite unique | H25: Temps de détection | M25: Emergence | W25: CH4 | Y25: N2 | AA25: CO2
E26: Test | F26: % | H26: Détectés | I26: =IFERROR(__xludf.DUMMYFUNCTION("COUNT(FILTER(Tests!C$4:C989, Tests!C$4:C989>=$B18, Tests!C$4:C989<=$B19, Tests!BS$4:BS989>0))"),276.0) -> 276 | M26: Test | N26: % | W26: Test | X26: % | Y26: Test | Z26: % | AA26: Test | AB26: %
D27: Détectés | E27: =IFERROR(__xludf.DUMMYFUNCTION("COUNT(FILTER(Tests!C$4:C989, Tests!C$4:C989>=$B18, Tests!C$4:C989<=$B19, Tests!BS$4:BS989>0, Tests!U$4:U989>=1, Tests!AU$4:AU989<>""Y"", Tests!N$4:N989=""North""))"),93.0) -> 93 | F27: =E27/E29 -> 0.65957447 | H27: Moyenne (m) | I27: =IFERROR(__xludf.DUMMYFUNCTION("AVERAGE(FILTER(Tests!$BV$4:$BV989, Tests!$C$4:$C989>=$B$18, Tests!$C$4:$C989<=$B$19, Tests!$BS$4:$BS989>0))"),0.0024690782200110554) -> 0.0024690782 | L27: Mesurée | M27: =IFERROR(__xludf.DUMMYFUNCTION("COUNT(FILTER(Tests!C$4:C989, Tests!C$4:C989>=$B18, Tests!C$4:C989<=$B19, Tests!CK$4:CK989>0))"),250.0) -> 250 | N27: =M27/M29 -> 0.47528517 | V27: Détectés | W27: =IFERROR(__xludf.DUMMYFUNCTION("COUNT(FILTER(Tests!C$4:C989, Tests!C$4:C989>=$B18, Tests!C$4:C989<=$B19, Tests!BS$4:BS989>0, Tests!M$4:M989=""CH4""))"),222.0) -> 222 | X27: =W27/W29 -> 0.51748252 | Y27: =IFERROR(__xludf.DUMMYFUNCTION("COUNT(FILTER(Tests!C$4:C989, Tests!C$4:C989>=$B18, Tests!C$4:C989<=$B19, Tests!BS$4:BS989>0, Tests!M$4:M989=""N2""))"),28.0) -> 28 | Z27: =Y27/Y29 -> 0.58333333 | AA27: =IFERROR(__xludf.DUMMYFUNCTION("COUNT(FILTER(Tests!C$4:C989, Tests!C$4:C989>=$B18, Tests!C$4:C989<=$B19, Tests!BS$4:BS989>0, Tests!M$4:M989=""CO2""))"),13.0) -> 13 | AB27: =AA27/AA29 -> 0.40625
D28: Non détectés | E28: =IFERROR(__xludf.DUMMYFUNCTION("COUNT(FILTER(Tests!C$4:C989, Tests!C$4:C989>=$B18, Tests!C$4:C989<=$B19, Tests!BS$4:BS989=0, Tests!BS$4:BS989<>"""", Tests!U$4:U989>=1, Tests!AU$4:AU989<>""Y"", Tests!N$4:N989=""North""))"),48.0) -> 48 | F28: =E28/E29 -> 0.34042553 | H28: Médiane (m) | I28: =IFERROR(__xludf.DUMMYFUNCTION("MEDIAN(FILTER(Tests!$BV$4:$BV989, Tests!$C$4:$C989>=$B$18, Tests!$C$4:$C989<=$B$19, Tests!$BS$4:$BS989>0))"),6.249999999999867E-4) -> 0.000625 | L28: Non mesurée | M28: =IFERROR(__xludf.DUMMYFUNCTION("COUNT(FILTER(Tests!C$4:C989, Tests!C$4:C989>=$B18, Tests!C$4:C989<=$B19, Tests!CK$4:CK989=0, Tests!CK$4:CK989<>""""))"),276.0) -> 276 | N28: =M28/M29 -> 0.52471483 | V28: Non détectés | W28: =IFERROR(__xludf.DUMMYFUNCTION("COUNT(FILTER(Tests!C$4:C989, Tests!C$4:C989>=$B18, Tests!C$4:C989<=$B19, Tests!BS$4:BS989=0, Tests!BS$4:BS989<>"""", Tests!M$4:M989=""CH4""))"),207.0) -> 207 | X28: =W28/W29 -> 0.48251748 | Y28: =IFERROR(__xludf.DUMMYFUNCTION("COUNT(FILTER(Tests!C$4:C989, Tests!C$4:C989>=$B18, Tests!C$4:C989<=$B19, Tests!BS$4:BS989=0, Tests!BS$4:BS989<>"""", Tests!M$4:M989=""N2""))"),20.0) -> 20 | Z28: =Y28/Y29 -> 0.41666667 | AA28: =IFERROR(__xludf.DUMMYFUNCTION("COUNT(FILTER(Tests!C$4:C989, Tests!C$4:C989>=$B18, Tests!C$4:C989<=$B19, Tests!BS$4:BS989=0, Tests!BS$4:BS989<>"""", Tests!M$4:M989=""CO2""))"),19.0) -> 19 | AB28: =AA28/AA29 -> 0.59375
D29: Total | E29: =SUM(E27:E28) -> 141 | H29: Maximum (m) | I29: =IFERROR(__xludf.DUMMYFUNCTION("MAX(FILTER(Tests!$BV$4:$BV989, Tests!$C$4:$C989>=$B$18, Tests!$C$4:$C989<=$B$19, Tests!$BS$4:$BS989>0))"),0.03388888888888886) -> 0.033888889 | L29: Total | M29: =SUM(M27:M28) -> 526 | V29: Total | W29: =W27+W28 -> 429 | Y29: =Y27+Y28 -> 48 | AA29: =AA27+AA28 -> 32
D30: Non adaptés | E30: =B$20-E29 -> 385 | H30: Minimum (m) | I30: =IFERROR(__xludf.DUMMYFUNCTION("MIN(FILTER(Tests!$BV$4:$BV989, Tests!$C$4:$C989>=$B$18, Tests!$C$4:$C989<=$B$19, Tests!$BS$4:$BS989>0))"),3.472222222222765E-5) -> 3.4722222e-05 | L30: Non renseignés | M30: =B20-M29 -> 0
W31: flowrate >= diameter | Y31: flowrate < diameter
D32: Equipement | E32: Détectés | F32: Non-Détectés | G32: % | H32: Emergence | P32: Type | Q32: Détectés | R32: Non-Détectés | S32: % | T32: Emergence | W32: Test | X32: % | Y32: Test | Z32: %
D33: Total | E33: =SUM(E34:E50) -> 252 | F33: =SUM(F34:F50) -> 217 | G33: =E33/(E33+F33) -> 0.53731343 | H33: =SUM(H34:H46) -> 187 | P33: Total | Q33: =SUM(Q34:Q60) -> 275 | R33: =SUM(R34:R60) -> 249 | S33: =Q33/(Q33+R33) -> 0.52480916 | T33: =SUM(T34:T60) -> 250 | V33: Détectés | W33: =IFERROR(__xludf.DUMMYFUNCTION("COUNT(FILTER(Tests!C$4:C989, Tests!C$4:C989>=$B18, Tests!C$4:C989<=$B19, Tests!BS$4:BS989>0, Tests!U4:U989>=Tests!AC4:AC989))"),89.0) -> 89 | X33: =W33/W35 -> 0.64028777 | Y33: =IFERROR(__xludf.DUMMYFUNCTION("COUNT(FILTER(Tests!C$4:C989, Tests!C$4:C989>=$B18, Tests!C$4:C989<=$B19, Tests!BS$4:BS989>0, Tests!U4:U989<Tests!AC4:AC989))"),187.0) -> 187 | Z33: =Y33/Y35 -> 0.48445596
D34: =IFERROR(__xludf.DUMMYFUNCTION("SORT(UNIQUE(FILTER(Tests!O$4:O989, Tests!C$4:C989>=$B18, Tests!C$4:C989<=$B19)))"),"Autre") -> Autre | E34: =IFERROR(__xludf.DUMMYFUNCTION("COUNT(FILTER(Tests!C$4:C989, Tests!C$4:C989>=$B$18, Tests!C$4:C989<=$B$19, Tests!BS$4:BS989>0, Tests!O$4:O989=D34))"),3.0) -> 3 | F34: =IFERROR(__xludf.DUMMYFUNCTION("COUNT(FILTER(Tests!C$4:C989, Tests!C$4:C989>=$B$18, Tests!C$4:C989<=$B$19, Tests!BS$4:BS989=0, Tests!BS$4:BS989<>"""", Tests!O$4:O989=D34))"),0.0) -> 0 | G34: =E34/(E34+F34) -> 1 | H34: =IFERROR(__xludf.DUMMYFUNCTION("COUNT(FILTER(Tests!C$4:C989, Tests!C$4:C989>=$B$18, Tests!C$4:C989<=$B$19, Tests!CK$4:CK989>0, Tests!O$4:O989=D34))"),0.0) -> 0 | P34: =IFERROR(__xludf.DUMMYFUNCTION("SORT(UNIQUE(FILTER(Tests!P$4:P989, Tests!C$4:C989>=$B18, Tests!C$4:C989<=$B19)))"),"Bottom flange") -> Bottom flange | Q34: =IFERROR(__xludf.DUMMYFUNCTION("COUNT(FILTER(Tests!C$4:C989, Tests!C$4:C989>=$B$18, Tests!C$4:C989<=$B$19, Tests!BS$4:BS989>0, Tests!P$4:P989=P34))"),7.0) -> 7 | R34: =IFERROR(__xludf.DUMMYFUNCTION("COUNT(FILTER(Tests!C$4:C989, Tests!C$4:C989>=$B$18, Tests!C$4:C989<=$B$19, Tests!BS$4:BS989=0, Tests!BS$4:BS989<>"""", Tests!P$4:P989=P34))"),8.0) -> 8 | S34: =Q34/(Q34+R34) -> 0.46666667 | T34: =IFERROR(__xludf.DUMMYFUNCTION("COUNT(FILTER(Tests!C$4:C989, Tests!C$4:C989>=$B$18, Tests!C$4:C989<=$B$19, Tests!CK$4:CK989>0, Tests!P$4:P989=P34))"),5.0) -> 5 | V34: Non détectés | W34: =IFERROR(__xludf.DUMMYFUNCTION("COUNT(FILTER(Tests!C$4:C989, Tests!C$4:C989>=$B18, Tests!C$4:C989<=$B19, Tests!BS$4:BS989=0, Tests!BS$4:BS989<>"""", Tests!U4:U989>=Tests!AC4:AC989))"),50.0) -> 50 | X34: =W34/W35 -> 0.35971223 | Y34: =IFERROR(__xludf.DUMMYFUNCTION("COUNT(FILTER(Tests!C$4:C989, Tests!C$4:C989>=$B18, Tests!C$4:C989<=$B19, Tests!BS$4:BS989=0, Tests!BS$4:BS989<>"""", Tests!U4:U989<Tests!AC4:AC989))"),199.0) -> 199 | Z34: =Y34/Y35 -> 0.51554404
D35: =IFERROR(__xludf.DUMMYFUNCTION("""COMPUTED_VALUE"""),"Fixed Point 1") -> Fixed Point 1 | E35: =IFERROR(__xludf.DUMMYFUNCTION("COUNT(FILTER(Tests!C$4:C989, Tests!C$4:C989>=$B$18, Tests!C$4:C989<=$B$19, Tests!BS$4:BS989>0, Tests!O$4:O989=D35))"),77.0) -> 77 | F35: =IFERROR(__xludf.DUMMYFUNCTION("COUNT(FILTER(Tests!C$4:C989, Tests!C$4:C989>=$B$18, Tests!C$4:C989<=$B$19, Tests!BS$4:BS989=0, Tests!BS$4:BS989<>"""", Tests!O$4:O989=D35))"),22.0) -> 22 | G35: =E35/(E35+F35) -> 0.77777778 | H35: =IFERROR(__xludf.DUMMYFUNCTION("COUNT(FILTER(Tests!C$4:C989, Tests!C$4:C989>=$B$18, Tests!C$4:C989<=$B$19, Tests!CK$4:CK989>0, Tests!O$4:O989=D35))"),61.0) -> 61 | P35: =IFERROR(__xludf.DUMMYFUNCTION("""COMPUTED_VALUE"""),"Connecting Flange") -> Connecting Flange | Q35: =IFERROR(__xludf.DUMMYFUNCTION("COUNT(FILTER(Tests!C$4:C989, Tests!C$4:C989>=$B$18, Tests!C$4:C989<=$B$19, Tests!BS$4:BS989>0, Tests!P$4:P989=P35))"),0.0) -> 0 | R35: =IFERROR(__xludf.DUMMYFUNCTION("COUNT(FILTER(Tests!C$4:C989, Tests!C$4:C989>=$B$18, Tests!C$4:C989<=$B$19, Tests!BS$4:BS989=0, Tests!BS$4:BS989<>"""", Tests!P$4:P989=P35))"),1.0) -> 1 | S35: =Q35/(Q35+R35) -> 0 | T35: =IFERROR(__xludf.DUMMYFUNCTION("COUNT(FILTER(Tests!C$4:C989, Tests!C$4:C989>=$B$18, Tests!C$4:C989<=$B$19, Tests!CK$4:CK989>0, Tests!P$4:P989=P35))"),0.0) -> 0 | V35: Total | W35: =W33+W34 -> 139 | Y35: =Y33+Y34 -> 386
D36: =IFERROR(__xludf.DUMMYFUNCTION("""COMPUTED_VALUE"""),"Fixed Point 2") -> Fixed Point 2 | E36: =IFERROR(__xludf.DUMMYFUNCTION("COUNT(FILTER(Tests!C$4:C989, Tests!C$4:C989>=$B$18, Tests!C$4:C989<=$B$19, Tests!BS$4:BS989>0, Tests!O$4:O989=D36))"),17.0) -> 17 | F36: =IFERROR(__xludf.DUMMYFUNCTION("COUNT(FILTER(Tests!C$4:C989, Tests!C$4:C989>=$B$18, Tests!C$4:C989<=$B$19, Tests!BS$4:BS989=0, Tests!BS$4:BS989<>"""", Tests!O$4:O989=D36))"),22.0) -> 22 | G36: =E36/(E36+F36) -> 0.43589744 | H36: =IFERROR(__xludf.DUMMYFUNCTION("COUNT(FILTER(Tests!C$4:C989, Tests!C$4:C989>=$B$18, Tests!C$4:C989<=$B$19, Tests!CK$4:CK989>0, Tests!O$4:O989=D36))"),29.0) -> 29 | P36: =IFERROR(__xludf.DUMMYFUNCTION("""COMPUTED_VALUE"""),"Connector") -> Connector | Q36: =IFERROR(__xludf.DUMMYFUNCTION("COUNT(FILTER(Tests!C$4:C989, Tests!C$4:C989>=$B$18, Tests!C$4:C989<=$B$19, Tests!BS$4:BS989>0, Tests!P$4:P989=P36))"),3.0) -> 3 | R36: =IFERROR(__xludf.DUMMYFUNCTION("COUNT(FILTER(Tests!C$4:C989, Tests!C$4:C989>=$B$18, Tests!C$4:C989<=$B$19, Tests!BS$4:BS989=0, Tests!BS$4:BS989<>"""", Tests!P$4:P989=P36))"),6.0) -> 6 | S36: =Q36/(Q36+R36) -> 0.33333333 | T36: =IFERROR(__xludf.DUMMYFUNCTION("COUNT(FILTER(Tests!C$4:C989, Tests!C$4:C989>=$B$18, Tests!C$4:C989<=$B$19, Tests!CK$4:CK989>0, Tests!P$4:P989=P36))"),5.0) -> 5
D37: =IFERROR(__xludf.DUMMYFUNCTION("""COMPUTED_VALUE"""),"Flare (6,5 m)") -> Flare (6,5 m) | E37: =IFERROR(__xludf.DUMMYFUNCTION("COUNT(FILTER(Tests!C$4:C989, Tests!C$4:C989>=$B$18, Tests!C$4:C989<=$B$19, Tests!BS$4:BS989>0, Tests!O$4:O989=D37))"),14.0) -> 14 | F37: =IFERROR(__xludf.DUMMYFUNCTION("COUNT(FILTER(Tests!C$4:C989, Tests!C$4:C989>=$B$18, Tests!C$4:C989<=$B$19, Tests!BS$4:BS989=0, Tests!BS$4:BS989<>"""", Tests!O$4:O989=D37))"),17.0) -> 17 | G37: =E37/(E37+F37) -> 0.4516129 | H37: =IFERROR(__xludf.DUMMYFUNCTION("COUNT(FILTER(Tests!C$4:C989, Tests!C$4:C989>=$B$18, Tests!C$4:C989<=$B$19, Tests!CK$4:CK989>0, Tests!O$4:O989=D37))"),21.0) -> 21 | P37: =IFERROR(__xludf.DUMMYFUNCTION("""COMPUTED_VALUE"""),"Control Box") -> Control Box | Q37: =IFERROR(__xludf.DUMMYFUNCTION("COUNT(FILTER(Tests!C$4:C989, Tests!C$4:C989>=$B$18, Tests!C$4:C989<=$B$19, Tests!BS$4:BS989>0, Tests!P$4:P989=P37))"),10.0) -> 10 | R37: =IFERROR(__xludf.DUMMYFUNCTION("COUNT(FILTER(Tests!C$4:C989, Tests!C$4:C989>=$B$18, Tests!C$4:C989<=$B$19, Tests!BS$4:BS989=0, Tests!BS$4:BS989<>"""", Tests!P$4:P989=P37))"),4.0) -> 4 | S37: =Q37/(Q37+R37) -> 0.71428571 | T37: =IFERROR(__xludf.DUMMYFUNCTION("COUNT(FILTER(Tests!C$4:C989, Tests!C$4:C989>=$B$18, Tests!C$4:C989<=$B$19, Tests!CK$4:CK989>0, Tests!P$4:P989=P37))"),9.0) -> 9
D38: =IFERROR(__xludf.DUMMYFUNCTION("""COMPUTED_VALUE"""),"Large Tank D1") -> Large Tank D1 | E38: =IFERROR(__xludf.DUMMYFUNCTION("COUNT(FILTER(Tests!C$4:C989, Tests!C$4:C989>=$B$18, Tests!C$4:C989<=$B$19, Tests!BS$4:BS989>0, Tests!O$4:O989=D38))"),6.0) -> 6 | F38: =IFERROR(__xludf.DUMMYFUNCTION("COUNT(FILTER(Tests!C$4:C989, Tests!C$4:C989>=$B$18, Tests!C$4:C989<=$B$19, Tests!BS$4:BS989=0, Tests!BS$4:BS989<>"""", Tests!O$4:O989=D38))"),15.0) -> 15 | G38: =E38/(E38+F38) -> 0.28571429 | H38: =IFERROR(__xludf.DUMMYFUNCTION("COUNT(FILTER(Tests!C$4:C989, Tests!C$4:C989>=$B$18, Tests!C$4:C989<=$B$19, Tests!CK$4:CK989>0, Tests!O$4:O989=D38))"),10.0) -> 10 | P38: =IFERROR(__xludf.DUMMYFUNCTION("""COMPUTED_VALUE"""),"Drilled Plug") -> Drilled Plug | Q38: =IFERROR(__xludf.DUMMYFUNCTION("COUNT(FILTER(Tests!C$4:C989, Tests!C$4:C989>=$B$18, Tests!C$4:C989<=$B$19, Tests!BS$4:BS989>0, Tests!P$4:P989=P38))"),49.0) -> 49 | R38: =IFERROR(__xludf.DUMMYFUNCTION("COUNT(FILTER(Tests!C$4:C989, Tests!C$4:C989>=$B$18, Tests!C$4:C989<=$B$19, Tests!BS$4:BS989=0, Tests!BS$4:BS989<>"""", Tests!P$4:P989=P38))"),23.0) -> 23 | S38: =Q38/(Q38+R38) -> 0.68055556 | T38: =IFERROR(__xludf.DUMMYFUNCTION("COUNT(FILTER(Tests!C$4:C989, Tests!C$4:C989>=$B$18, Tests!C$4:C989<=$B$19, Tests!CK$4:CK989>0, Tests!P$4:P989=P38))"),36.0) -> 36
D39: =IFERROR(__xludf.DUMMYFUNCTION("""COMPUTED_VALUE"""),"Long Tank D3") -> Long Tank D3 | E39: =IFERROR(__xludf.DUMMYFUNCTION("COUNT(FILTER(Tests!C$4:C989, Tests!C$4:C989>=$B$18, Tests!C$4:C989<=$B$19, Tests!BS$4:BS989>0, Tests!O$4:O989=D39))"),21.0) -> 21 | F39: =IFERROR(__xludf.DUMMYFUNCTION("COUNT(FILTER(Tests!C$4:C989, Tests!C$4:C989>=$B$18, Tests!C$4:C989<=$B$19, Tests!BS$4:BS989=0, Tests!BS$4:BS989<>"""", Tests!O$4:O989=D39))"),11.0) -> 11 | G39: =E39/(E39+F39) -> 0.65625 | H39: =IFERROR(__xludf.DUMMYFUNCTION("COUNT(FILTER(Tests!C$4:C989, Tests!C$4:C989>=$B$18, Tests!C$4:C989<=$B$19, Tests!CK$4:CK989>0, Tests!O$4:O989=D39))"),24.0) -> 24 | P39: =IFERROR(__xludf.DUMMYFUNCTION("""COMPUTED_VALUE"""),"Flange") -> Flange | Q39: =IFERROR(__xludf.DUMMYFUNCTION("COUNT(FILTER(Tests!C$4:C989, Tests!C$4:C989>=$B$18, Tests!C$4:C989<=$B$19, Tests!BS$4:BS989>0, Tests!P$4:P989=P39))"),8.0) -> 8 | R39: =IFERROR(__xludf.DUMMYFUNCTION("COUNT(FILTER(Tests!C$4:C989, Tests!C$4:C989>=$B$18, Tests!C$4:C989<=$B$19, Tests!BS$4:BS989=0, Tests!BS$4:BS989<>"""", Tests!P$4:P989=P39))"),7.0) -> 7 | S39: =Q39/(Q39+R39) -> 0.53333333 | T39: =IFERROR(__xludf.DUMMYFUNCTION("COUNT(FILTER(Tests!C$4:C989, Tests!C$4:C989>=$B$18, Tests!C$4:C989<=$B$19, Tests!CK$4:CK989>0, Tests!P$4:P989=P39))"),10.0) -> 10
